Workbook
Name anno: "2025"
Name cell_perc_RR: 10
Name mese: "10"
Name quarter: "Q4"

Sheet Budget
A1: FORMULA | K1: TO UPDATE BY SOFTWARE
A2: da considerare?_ | B2: BusinessArea_ | C2: ProjType_ | D2: ProjType Cluster 1_ | E2: ProjType Cluster 2_ | F2: Nome progetto_ | G2: EngUnit area cluster 1_ | H2: BDG est_ | I2: BDG int_ | J2: BDG_ | K2: Business | L2: CATEGORIA | M2: INT | N2: EST | O2: totale Gamberini | P2: INT2 | Q2: EST3 | R2: totale Lanzarini | S2: TOTALE TOT
A3: =IF(AND(tblBudget[[#This Row],[Business ]]>"",tblBudget[[#This Row],[CATEGORIA]]=""),"no","sì") -> sì | B3: =tblBudget[[#This Row],[Business ]] -> Business Sample | C3: =INDEX(tab_ProjTypeCluster[ProjType],MATCH(tblBudget[[#This Row],[CATEGORIA]],tab_ProjTypeCluster[Macro area],0)) -> #N/A | D3: =INDEX(tab_ProjTypeCluster[ProjType Cluster 1],MATCH(tblBudget[[#This Row],[CATEGORIA]],tab_ProjTypeCluster[Macro area],0)) -> #N/A | E3: =INDEX(tab_ProjTypeCluster[ProjType Cluster 2],MATCH(tblBudget[[#This Row],[CATEGORIA]],tab_ProjTypeCluster[Macro area],0)) -> #N/A | G3: =INDEX(tab_resp1liv[EngUnit area cluster 1_],MATCH(SUBSTITUTE(SUBSTITUTE(#REF!,"(ai)","")," ",""),tab_resp1liv[SearchKey],0)) -> #REF! | H3: =tblBudget[[#This Row],[EST]]+tblBudget[[#This Row],[EST3]] -> 15 | I3: =tblBudget[[#This Row],[INT]]+tblBudget[[#This Row],[INT2]] -> 25 | J3: =tblBudget[[#This Row],[TOTALE TOT]] -> 80 | K3: Business Sample | L3: Categoria A | M3: 10 | N3: 12 | O3: 22 | P3: 15 | Q3: 3 | R3: 18 | S3: 80

Sheet Forecast
A1: FORMULA | P1: TO UPDATE BY SOFTWARE
A2: da considerare? | B2: Proj type cluster 1 | C2: Proj type cluster 2 | D2: Business | E2: CATEGORIA_ | F2: ENG TOB - INT_ | G2: ENG TOB - EST_ | H2: ENG TOB Totale_ | I2: ENG LPP - INT_ | J2: ENG LPP - EST_ | K2: ENG LPP Totale_ | L2: int FORECAST_ | M2: ext FORECAST_ | N2: FORECAST Totale_ | O2: CATEGORIA TMP | P2: Business | Q2: CATEGORIA | R2: INT | S2: EST | T2: totale Gamberini | U2: INT2 | V2: EST3 | W2: totale Lanzarini | X2: TOTALE TOT
A3: =IF(AND(tblForecast[[#This Row],[Business ]]>"",tblForecast[[#This Row],[CATEGORIA]]=""),"no","sì") -> sì | B3: =IF(tblForecast[[#This Row],[da considerare?]]="sì",INDEX(tab_ProjType[ProjType Cluster 1],MATCH(tblForecast[[#This Row],[CATEGORIA TMP]],tab_ProjType[Macro area],0)),"") -> #N/A | C3: =IF(tblForecast[[#This Row],[da considerare?]]="sì",INDEX(tab_ProjType[ProjType Cluster 2],MATCH(tblForecast[[#This Row],[CATEGORIA TMP]],tab_ProjType[Macro area],0)),"") -> #N/A | D3: =IF(tblForecast[[#This Row],[Business ]]>"",tblForecast[[#This Row],[Business ]],D2) -> Business Sample | E3: =tblForecast[[#This Row],[CATEGORIA TMP]]&"" -> Categoria A | F3: =tblForecast[[#This Row],[INT]] -> 10 | G3: =tblForecast[[#This Row],[EST]] -> 12 | H3: =tblForecast[[#This Row],[totale Gamberini]] -> 22 | I3: =tblForecast[[#This Row],[INT2]] -> 15 | J3: =tblForecast[[#This Row],[EST3]] -> 3 | K3: =tblForecast[[#This Row],[totale Lanzarini]] -> 18 | L3: =tblForecast[[#This Row],[INT]]+tblForecast[[#This Row],[INT2]] -> 25 | M3: =tblForecast[[#This Row],[EST]]+tblForecast[[#This Row],[EST3]] -> 15 | N3: =tblForecast[[#This Row],[TOTALE TOT]] -> 80 | O3: =IF(LEFT(tblForecast[[#This Row],[CATEGORIA]],3)="R&D","R&D",tblForecast[[#This Row],[CATEGORIA]]) -> Categoria A | P3: Business Sample | Q3: Categoria A | R3: 10 | S3: 12 | T3: 22 | U3: 15 | V3: 3 | W3: 18 | X3: 80

Sheet RunRate
A1: 01 | B1: 02 | C1: 03 | D1: 04 | E1: 05 | F1: 06 | G1: 07 | H1: 08 | I1: 09 | J1: 10 | K1: 11 | L1: 12
A2: 0.15 | B2: 0.1 | C2: 0.05 | D2: 0.1 | E2: 0.15 | F2: 0.2 | G2: 0.25 | H2: 0.2 | I2: 0.15 | J2: 0.1 | K2: 0.05 | L2: 0.1

Sheet Superdetails
A1: FORMULA | AE1: TO UPDATE BY SOFTWARE
A2: da considerare?_ | B2: Anno_ | C2: Anno di prima marcatura (=anno di apertura progetto) | D2: WBS_ | E2: ProjType_ | F2: U ProjType_ | G2: ProjType Cluster | H2: ProjType Cluster2 | I2: BussinessArea Cluster | J2: ORE_ | K2: gen_ | L2: feb_ | M2: mar_ | N2: apr_ | O2: mag_ | P2: giu_ | Q2: lug_ | R2: ago_ | S2: set_ | T2: ott_ | U2: nov_ | V2: dic_ | W2: tipo risorsa_ | X2: Resp 1°liv_ | Y2: EngUnit area cluster 1_ | Z2: WBS description_ | AA2: WBE description_ | AB2: WBS D description_ | AC2: WBS M description_ | AD2: WBE per WBS-K | AE2: Sender Cost Center | AF2: Personnel Number | AG2: Last name First name | AH2: Project Description | AI2: WBS Element | AJ2: Network | AK2: Operation/Activity | AL2: Acct assgnt text | AM2: WBS Element - Project Definition (Text) | AN2: Network descr | AO2: PROJ CODE | AP2: INT/EST | AQ2: Raggr. X Struttura | AR2: MESE | AS2: Resp 2°liv | AT2: CDC bdg | AU2: Resp 1°liv | AV2: Resp DT | AW2: TIPO REP | AX2: Bus Area GDLT | AY2: Bus Area_2 | AZ2: tipo progetto | BA2: Proj name | BB2: machine code | BC2: product area | BD2: Resp del Prodotto | BE2: Area di bdg | BF2: Macchina | BG2: Sottotipo | BH2: Cluster | BI2: Quadrante | BJ2: 01.2025 | BK2: 02.2025 | BL2: 03.2025 | BM2: 04.2025 | BN2: 05.2025 | BO2: 06.2025 | BP2: 07.2025 | BQ2: 08.2025 | BR2: 09.2025 | BS2: 10.2025 | BT2: 11.2025 | BU2: 12.2025 | BV2: Total | BW2: WBE Status | BX2: competence date | BY2: Proj. Type | BZ2: WBE Name | CA2: Engineering Area | CB2: Data Accettazione | CC2: Data Uscita GD | CD2: REP UT
A3: =IF(UPPER(LEFT(tabSuperdettagli[[#This Row],[WBE Status]],1))="S","sì","no") -> no | B3: 2015 | C3: =VLOOKUP(tabSuperdettagli[[#This Row],[WBS_]],Pivot_AnnoPrimaMarcatura!A:B,2,FALSE) -> #N/A | D3: =LEFT(tabSuperdettagli[[#This Row],[Network]],10) | E3: =LEFT(tabSuperdettagli[[#This Row],[Network]],1) | F3: =LOWER(TRIM(tabSuperdettagli[[#This Row],[Proj. Type ]])) | G3: =IF(OR(tabSuperdettagli[[#This Row],[ProjType_]]="C",tabSuperdettagli[[#This Row],[ProjType_]]="A",tabSuperdettagli[[#This Row],[ProjType_]]="R",tabSuperdettagli[[#This Row],[ProjType_]]="E"),"C A R E",IF(tabSuperdettagli[[#This Row],[ProjType_]]="U","U ("&tabSuperdettagli[[#This Row],[U ProjType_]]&")",tabSuperdettagli[[#This Row],[ProjType_]])) | I3: =IF( TRIM(tabSuperdettagli[[#This Row],[Raggr. X Struttura]])> "", TRIM(tabSuperdettagli[[#This Row],[Raggr. X Struttura]]), TRIM(tabSuperdettagli[[#This Row],[Resp DT]] ) ) -> Gruppo struttura 1 | J3: =tabSuperdettagli[[#This Row],[Total]] -> 55 | K3: =tabSuperdettagli[[#This Row],[01.2025]] -> 1 | L3: =tabSuperdettagli[[#This Row],[02.2025]] -> 2 | M3: =tabSuperdettagli[[#This Row],[03.2025]] -> 3 | N3: =tabSuperdettagli[[#This Row],[04.2025]] -> 4 | O3: =tabSuperdettagli[[#This Row],[05.2025]] -> 5 | P3: =tabSuperdettagli[[#This Row],[06.2025]] -> 6 | Q3: =tabSuperdettagli[[#This Row],[07.2025]] -> 7 | R3: =tabSuperdettagli[[#This Row],[08.2025]] -> 8 | S3: =tabSuperdettagli[[#This Row],[09.2025]] -> 9 | T3: =tabSuperdettagli[[#This Row],[10.2025]] -> 10 | U3: =tabSuperdettagli[[#This Row],[11.2025]] -> 0 | V3: =tabSuperdettagli[[#This Row],[12.2025]] -> 0 | W3: =tabSuperdettagli[[#This Row],[INT/EST]] -> Int. | X3: =tabSuperdettagli[[#This Row],[Resp 2°liv]]&"" | Y3: =INDEX(tab_resp1liv[EngUnit area cluster 1_],MATCH(SUBSTITUTE(tabSuperdettagli[[#This Row],[Resp 2°liv]]," ",""),tab_resp1liv[SearchKey],0)) -> #N/A | Z3: =tabSuperdettagli[[#This Row],[WBS Element]]&"" | AA3: =tabSuperdettagli[[#This Row],[09.2025]] -> 9 | AC3: =IF(tabSuperdettagli[[#This Row],[ProjType_]]="M",IF(AND(tabSuperdettagli[[#This Row],[Resp 1°liv_]]="Guidotti C.",tabSuperdettagli[[#This Row],[WBE description_]]="Machine Mgmt"),"Documentation",tabSuperdettagli[[#This Row],[WBE description_]]),"") | AD3: =LEFT(tabSuperdettagli[[#This Row],[Network]],18) | AE3: Send cost A | AP3: Int. | AQ3: Gruppo struttura 1 | AV3: Responsabile A | BJ3: 1 | BK3: 2 | BL3: 3 | BM3: 4 | BN3: 5 | BO3: 6 | BP3: 7 | BQ3: 8 | BR3: 9 | BS3: 10 | BV3: 55 | BX3: 42006 | CB3: 42005 | CC3: 42045
A4: =IF(UPPER(LEFT(tabSuperdettagli[[#This Row],[WBE Status]],1))="S","sì","no") -> no | B4: 2015 | C4: =VLOOKUP(tabSuperdettagli[[#This Row],[WBS_]],Pivot_AnnoPrimaMarcatura!A:B,2,FALSE) -> #N/A | D4: =LEFT(tabSuperdettagli[[#This Row],[Network]], 10) | E4: =LEFT(tabSuperdettagli[[#This Row],[Network]], 1) | F4: =LOWER(TRIM( tabSuperdettagli[[#This Row],[Proj. Type ]] )) | G4: =IF( OR( tabSuperdettagli[[#This Row],[ProjType_]]="C", tabSuperdettagli[[#This Row],[ProjType_]]="A", tabSuperdettagli[[#This Row],[ProjType_]]="R", tabSuperdettagli[[#This Row],[ProjType_]]="E"), "C A R E", IF( tabSuperdettagli[[#This Row],[ProjType_]]="U", "U (" & tabSuperdettagli[[#This Row],[U ProjType_]] & ")", tabSuperdettagli[[#This Row],[ProjType_]]) ) | I4: =IF( TRIM(tabSuperdettagli[[#This Row],[Raggr. X Struttura]])> "", TRIM(tabSuperdettagli[[#This Row],[Raggr. X Struttura]]), TRIM(tabSuperdettagli[[#This Row],[Resp DT]] ) ) -> Gruppo struttura 1 | J4: =tabSuperdettagli[[#This Row],[Total]] -> 1055 | K4: =tabSuperdettagli[[#This Row],[01.2025]] -> 101 | L4: =tabSuperdettagli[[#This Row],[02.2025]] -> 102 | M4: =tabSuperdettagli[[#This Row],[03.2025]] -> 103 | N4: =tabSuperdettagli[[#This Row],[04.2025]] -> 104 | O4: =tabSuperdettagli[[#This Row],[05.2025]] -> 105 | P4: =tabSuperdettagli[[#This Row],[06.2025]] -> 106 | Q4: =tabSuperdettagli[[#This Row],[07.2025]] -> 107 | R4: =tabSuperdettagli[[#This Row],[08.2025]] -> 108 | S4: =tabSuperdettagli[[#This Row],[09.2025]] -> 109 | T4: =tabSuperdettagli[[#This Row],[10.2025]] -> 110 | U4: =tabSuperdettagli[[#This Row],[11.2025]] -> 0 | V4: =tabSuperdettagli[[#This Row],[12.2025]] -> 0 | W4: =tabSuperdettagli[[#This Row],[INT/EST]] -> Est. | X4: =tabSuperdettagli[[#This Row],[Resp 2°liv]]&"" | Y4: =INDEX( tab_resp1liv[EngUnit area cluster 1_], MATCH( SUBSTITUTE(tabSuperdettagli[[#This Row],[Resp 2°liv]], " ", ""), tab_resp1liv[SearchKey],0)) -> #N/A | Z4: =tabSuperdettagli[[#This Row],[WBS Element]]&"" | AA4: =tabSuperdettagli[[#This Row],[09.2025]] -> 109 | AC4: =IF( tabSuperdettagli[[#This Row],[ProjType_]]="M", IF( AND(tabSuperdettagli[[#This Row],[Resp 1°liv_]]="Guidotti C.", tabSuperdettagli[[#This Row],[WBE description_]]="Machine Mgmt"), "Documentation", tabSuperdettagli[[#This Row],[WBE description_]]), "" ) | AD4: =LEFT(tabSuperdettagli[[#This Row],[Network]], 18 ) | AE4: Send cost A | AP4: Est. | AQ4: Gruppo struttura 1 | AV4: Responsabile B | BJ4: 101 | BK4: 102 | BL4: 103 | BM4: 104 | BN4: 105 | BO4: 106 | BP4: 107 | BQ4: 108 | BR4: 109 | BS4: 110 | BV4: 1055 | BX4: 42009 | CB4: 42008 | CC4: 42048
A5: =IF(UPPER(LEFT(tabSuperdettagli[[#This Row],[WBE Status]],1))="S","sì","no") -> no | B5: 2015 | C5: =VLOOKUP(tabSuperdettagli[[#This Row],[WBS_]],Pivot_AnnoPrimaMarcatura!A:B,2,FALSE) -> #N/A | D5: =LEFT(tabSuperdettagli[[#This Row],[Network]], 10) | E5: =LEFT(tabSuperdettagli[[#This Row],[Network]], 1) | F5: =LOWER(TRIM( tabSuperdettagli[[#This Row],[Proj. Type ]] )) | G5: =IF( OR( tabSuperdettagli[[#This Row],[ProjType_]]="C", tabSuperdettagli[[#This Row],[ProjType_]]="A", tabSuperdettagli[[#This Row],[ProjType_]]="R", tabSuperdettagli[[#This Row],[ProjType_]]="E"), "C A R E", IF( tabSuperdettagli[[#This Row],[ProjType_]]="U", "U (" & tabSuperdettagli[[#This Row],[U ProjType_]] & ")", tabSuperdettagli[[#This Row],[ProjType_]]) ) | I5: =IF( TRIM(tabSuperdettagli[[#This Row],[Raggr. X Struttura]])> "", TRIM(tabSuperdettagli[[#This Row],[Raggr. X Struttura]]), TRIM(tabSuperdettagli[[#This Row],[Resp DT]] ) ) -> Gruppo struttura 2 | J5: =tabSuperdettagli[[#This Row],[Total]] -> 2055 | K5: =tabSuperdettagli[[#This Row],[01.2025]] -> 201 | L5: =tabSuperdettagli[[#This Row],[02.2025]] -> 202 | M5: =tabSuperdettagli[[#This Row],[03.2025]] -> 203 | N5: =tabSuperdettagli[[#This Row],[04.2025]] -> 204 | O5: =tabSuperdettagli[[#This Row],[05.2025]] -> 205 | P5: =tabSuperdettagli[[#This Row],[06.2025]] -> 206 | Q5: =tabSuperdettagli[[#This Row],[07.2025]] -> 207 | R5: =tabSuperdettagli[[#This Row],[08.2025]] -> 208 | S5: =tabSuperdettagli[[#This Row],[09.2025]] -> 209 | T5: =tabSuperdettagli[[#This Row],[10.2025]] -> 210 | U5: =tabSuperdettagli[[#This Row],[11.2025]] -> 0 | V5: =tabSuperdettagli[[#This Row],[12.2025]] -> 0 | W5: =tabSuperdettagli[[#This Row],[INT/EST]] -> Est. | X5: =tabSuperdettagli[[#This Row],[Resp 2°liv]]&"" | Y5: =INDEX( tab_resp1liv[EngUnit area cluster 1_], MATCH( SUBSTITUTE(tabSuperdettagli[[#This Row],[Resp 2°liv]], " ", ""), tab_resp1liv[SearchKey],0)) -> #N/A | Z5: =tabSuperdettagli[[#This Row],[WBS Element]]&"" | AA5: =tabSuperdettagli[[#This Row],[09.2025]] -> 209 | AC5: =IF( tabSuperdettagli[[#This Row],[ProjType_]]="M", IF( AND(tabSuperdettagli[[#This Row],[Resp 1°liv_]]="Guidotti C.", tabSuperdettagli[[#This Row],[WBE description_]]="Machine Mgmt"), "Documentation", tabSuperdettagli[[#This Row],[WBE description_]]), "" ) | AD5: =LEFT(tabSuperdettagli[[#This Row],[Network]], 18 ) | AE5: Send cost A | AP5: Est. | AQ5: Gruppo struttura 2 | AV5: Responsabile C | BJ5: 201 | BK5: 202 | BL5: 203 | BM5: 204 | BN5: 205 | BO5: 206 | BP5: 207 | BQ5: 208 | BR5: 209 | BS5: 210 | BV5: 2055 | BX5: 42012 | CB5: 42011 | CC5: 42051
A6: =IF(UPPER(LEFT(tabSuperdettagli[[#This Row],[WBE Status]],1))="S","sì","no") -> no | B6: 2015 | C6: =VLOOKUP(tabSuperdettagli[[#This Row],[WBS_]],Pivot_AnnoPrimaMarcatura!A:B,2,FALSE) -> #N/A | D6: =LEFT(tabSuperdettagli[[#This Row],[Network]], 10) | E6: =LEFT(tabSuperdettagli[[#This Row],[Network]], 1) | F6: =LOWER(TRIM( tabSuperdettagli[[#This Row],[Proj. Type ]] )) | G6: =IF( OR( tabSuperdettagli[[#This Row],[ProjType_]]="C", tabSuperdettagli[[#This Row],[ProjType_]]="A", tabSuperdettagli[[#This Row],[ProjType_]]="R", tabSuperdettagli[[#This Row],[ProjType_]]="E"), "C A R E", IF( tabSuperdettagli[[#This Row],[ProjType_]]="U", "U (" & tabSuperdettagli[[#This Row],[U ProjType_]] & ")", tabSuperdettagli[[#This Row],[ProjType_]]) ) | I6: =IF( TRIM(tabSuperdettagli[[#This Row],[Raggr. X Struttura]])> "", TRIM(tabSuperdettagli[[#This Row],[Raggr. X Struttura]]), TRIM(tabSuperdettagli[[#This Row],[Resp DT]] ) ) -> Gruppo struttura 1 | J6: =tabSuperdettagli[[#This Row],[Total]] -> 55 | K6: =tabSuperdettagli[[#This Row],[01.2025]] -> 1 | L6: =tabSuperdettagli[[#This Row],[02.2025]] -> 2 | M6: =tabSuperdettagli[[#This Row],[03.2025]] -> 3 | N6: =tabSuperdettagli[[#This Row],[04.2025]] -> 4 | O6: =tabSuperdettagli[[#This Row],[05.2025]] -> 5 | P6: =tabSuperdettagli[[#This Row],[06.2025]] -> 6 | Q6: =tabSuperdettagli[[#This Row],[07.2025]] -> 7 | R6: =tabSuperdettagli[[#This Row],[08.2025]] -> 8 | S6: =tabSuperdettagli[[#This Row],[09.2025]] -> 9 | T6: =tabSuperdettagli[[#This Row],[10.2025]] -> 10 | U6: =tabSuperdettagli[[#This Row],[11.2025]] -> 0 | V6: =tabSuperdettagli[[#This Row],[12.2025]] -> 0 | W6: =tabSuperdettagli[[#This Row],[INT/EST]] -> Int. | X6: =tabSuperdettagli[[#This Row],[Resp 2°liv]]&"" | Y6: =INDEX( tab_resp1liv[EngUnit area cluster 1_], MATCH( SUBSTITUTE(tabSuperdettagli[[#This Row],[Resp 2°liv]], " ", ""), tab_resp1liv[SearchKey],0)) -> #N/A | Z6: =tabSuperdettagli[[#This Row],[WBS Element]]&"" | AA6: =tabSuperdettagli[[#This Row],[09.2025]] -> 9 | AC6: =IF( tabSuperdettagli[[#This Row],[ProjType_]]="M", IF( AND(tabSuperdettagli[[#This Row],[Resp 1°liv_]]="Guidotti C.", tabSuperdettagli[[#This Row],[WBE description_]]="Machine Mgmt"), "Documentation", tabSuperdettagli[[#This Row],[WBE description_]]), "" ) | AD6: =LEFT(tabSuperdettagli[[#This Row],[Network]], 18 ) | AE6: Send cost A | AP6: Int. | AQ6: Gruppo struttura 1 | AV6: Responsabile A | BJ6: 1 | BK6: 2 | BL6: 3 | BM6: 4 | BN6: 5 | BO6: 6 | BP6: 7 | BQ6: 8 | BR6: 9 | BS6: 10 | BV6: 55 | BX6: 42015 | CB6: 42014 | CC6: 42054
A7: =IF(UPPER(LEFT(tabSuperdettagli[[#This Row],[WBE Status]],1))="S","sì","no") -> no | B7: 2015 | C7: =VLOOKUP(tabSuperdettagli[[#This Row],[WBS_]],Pivot_AnnoPrimaMarcatura!A:B,2,FALSE) -> #N/A | D7: =LEFT(tabSuperdettagli[[#This Row],[Network]], 10) | E7: =LEFT(tabSuperdettagli[[#This Row],[Network]], 1) | F7: =LOWER(TRIM( tabSuperdettagli[[#This Row],[Proj. Type ]] )) | G7: =IF( OR( tabSuperdettagli[[#This Row],[ProjType_]]="C", tabSuperdettagli[[#This Row],[ProjType_]]="A", tabSuperdettagli[[#This Row],[ProjType_]]="R", tabSuperdettagli[[#This Row],[ProjType_]]="E"), "C A R E", IF( tabSuperdettagli[[#This Row],[ProjType_]]="U", "U (" & tabSuperdettagli[[#This Row],[U ProjType_]] & ")", tabSuperdettagli[[#This Row],[ProjType_]]) ) | I7: =IF( TRIM(tabSuperdettagli[[#This Row],[Raggr. X Struttura]])> "", TRIM(tabSuperdettagli[[#This Row],[Raggr. X Struttura]]), TRIM(tabSuperdettagli[[#This Row],[Resp DT]] ) ) -> Gruppo struttura 4 | J7: =tabSuperdettagli[[#This Row],[Total]] -> 1055 | K7: =tabSuperdettagli[[#This Row],[01.2025]] -> 101 | L7: =tabSuperdettagli[[#This Row],[02.2025]] -> 102 | M7: =tabSuperdettagli[[#This Row],[03.2025]] -> 103 | N7: =tabSuperdettagli[[#This Row],[04.2025]] -> 104 | O7: =tabSuperdettagli[[#This Row],[05.2025]] -> 105 | P7: =tabSuperdettagli[[#This Row],[06.2025]] -> 106 | Q7: =tabSuperdettagli[[#This Row],[07.2025]] -> 107 | R7: =tabSuperdettagli[[#This Row],[08.2025]] -> 108 | S7: =tabSuperdettagli[[#This Row],[09.2025]] -> 109 | T7: =tabSuperdettagli[[#This Row],[10.2025]] -> 110 | U7: =tabSuperdettagli[[#This Row],[11.2025]] -> 0 | V7: =tabSuperdettagli[[#This Row],[12.2025]] -> 0 | W7: =tabSuperdettagli[[#This Row],[INT/EST]] -> Est. | X7: =tabSuperdettagli[[#This Row],[Resp 2°liv]]&"" | Y7: =INDEX( tab_resp1liv[EngUnit area cluster 1_], MATCH( SUBSTITUTE(tabSuperdettagli[[#This Row],[Resp 2°liv]], " ", ""), tab_resp1liv[SearchKey],0)) -> #N/A | Z7: =tabSuperdettagli[[#This Row],[WBS Element]]&"" | AA7: =tabSuperdettagli[[#This Row],[09.2025]] -> 109 | AC7: =IF( tabSuperdettagli[[#This Row],[ProjType_]]="M", IF( AND(tabSuperdettagli[[#This Row],[Resp 1°liv_]]="Guidotti C.", tabSuperdettagli[[#This Row],[WBE description_]]="Machine Mgmt"), "Documentation", tabSuperdettagli[[#This Row],[WBE description_]]), "" ) | AD7: =LEFT(tabSuperdettagli[[#This Row],[Network]], 18 ) | AE7: Send cost A | AP7: Est. | AQ7: Gruppo struttura 4 | AV7: Responsabile A | BJ7: 101 | BK7: 102 | BL7: 103 | BM7: 104 | BN7: 105 | BO7: 106 | BP7: 107 | BQ7: 108 | BR7: 109 | BS7: 110 | BV7: 1055 | BX7: 42018 | CB7: 42017 | CC7: 42057
A8: =IF(UPPER(LEFT(tabSuperdettagli[[#This Row],[WBE Status]],1))="S","sì","no") -> no | B8: 2015 | C8: =VLOOKUP(tabSuperdettagli[[#This Row],[WBS_]],Pivot_AnnoPrimaMarcatura!A:B,2,FALSE) -> #N/A | D8: =LEFT(tabSuperdettagli[[#This Row],[Network]], 10) | E8: =LEFT(tabSuperdettagli[[#This Row],[Network]], 1) | F8: =LOWER(TRIM( tabSuperdettagli[[#This Row],[Proj. Type ]] )) | G8: =IF( OR( tabSuperdettagli[[#This Row],[ProjType_]]="C", tabSuperdettagli[[#This Row],[ProjType_]]="A", tabSuperdettagli[[#This Row],[ProjType_]]="R", tabSuperdettagli[[#This Row],[ProjType_]]="E"), "C A R E", IF( tabSuperdettagli[[#This Row],[ProjType_]]="U", "U (" & tabSuperdettagli[[#This Row],[U ProjType_]] & ")", tabSuperdettagli[[#This Row],[ProjType_]]) ) | I8: =IF( TRIM(tabSuperdettagli[[#This Row],[Raggr. X Struttura]])> "", TRIM(tabSuperdettagli[[#This Row],[Raggr. X Struttura]]), TRIM(tabSuperdettagli[[#This Row],[Resp DT]] ) ) -> Gruppo struttura 3 | J8: =tabSuperdettagli[[#This Row],[Total]] -> 2055 | K8: =tabSuperdettagli[[#This Row],[01.2025]] -> 201 | L8: =tabSuperdettagli[[#This Row],[02.2025]] -> 202 | M8: =tabSuperdettagli[[#This Row],[03.2025]] -> 203 | N8: =tabSuperdettagli[[#This Row],[04.2025]] -> 204 | O8: =tabSuperdettagli[[#This Row],[05.2025]] -> 205 | P8: =tabSuperdettagli[[#This Row],[06.2025]] -> 206 | Q8: =tabSuperdettagli[[#This Row],[07.2025]] -> 207 | R8: =tabSuperdettagli[[#This Row],[08.2025]] -> 208 | S8: =tabSuperdettagli[[#This Row],[09.2025]] -> 209 | T8: =tabSuperdettagli[[#This Row],[10.2025]] -> 210 | U8: =tabSuperdettagli[[#This Row],[11.2025]] -> 0 | V8: =tabSuperdettagli[[#This Row],[12.2025]] -> 0 | W8: =tabSuperdettagli[[#This Row],[INT/EST]] -> Est. | X8: =tabSuperdettagli[[#This Row],[Resp 2°liv]]&"" | Y8: =INDEX( tab_resp1liv[EngUnit area cluster 1_], MATCH( SUBSTITUTE(tabSuperdettagli[[#This Row],[Resp 2°liv]], " ", ""), tab_resp1liv[SearchKey],0)) -> #N/A | Z8: =tabSuperdettagli[[#This Row],[WBS Element]]&"" | AA8: =tabSuperdettagli[[#This Row],[09.2025]] -> 209 | AC8: =IF( tabSuperdettagli[[#This Row],[ProjType_]]="M", IF( AND(tabSuperdettagli[[#This Row],[Resp 1°liv_]]="Guidotti C.", tabSuperdettagli[[#This Row],[WBE description_]]="Machine Mgmt"), "Documentation", tabSuperdettagli[[#This Row],[WBE description_]]), "" ) | AD8: =LEFT(tabSuperdettagli[[#This Row],[Network]], 18 ) | AE8: Send cost A | AP8: Est. | AQ8: Gruppo struttura 3 | AV8: Responsabile A | BJ8: 201 | BK8: 202 | BL8: 203 | BM8: 204 | BN8: 205 | BO8: 206 | BP8: 207 | BQ8: 208 | BR8: 209 | BS8: 210 | BV8: 2055 | BX8: 42021 | CB8: 42020 | CC8: 42060
A9: =IF(UPPER(LEFT(tabSuperdettagli[[#This Row],[WBE Status]],1))="S","sì","no") -> no | B9: 2015 | C9: =VLOOKUP(tabSuperdettagli[[#This Row],[WBS_]],Pivot_AnnoPrimaMarcatura!A:B,2,FALSE) -> #N/A | D9: =LEFT(tabSuperdettagli[[#This Row],[Network]], 10) | E9: =LEFT(tabSuperdettagli[[#This Row],[Network]], 1) | F9: =LOWER(TRIM( tabSuperdettagli[[#This Row],[Proj. Type ]] )) | G9: =IF( OR( tabSuperdettagli[[#This Row],[ProjType_]]="C", tabSuperdettagli[[#This Row],[ProjType_]]="A", tabSuperdettagli[[#This Row],[ProjType_]]="R", tabSuperdettagli[[#This Row],[ProjType_]]="E"), "C A R E", IF( tabSuperdettagli[[#This Row],[ProjType_]]="U", "U (" & tabSuperdettagli[[#This Row],[U ProjType_]] & ")", tabSuperdettagli[[#This Row],[ProjType_]]) ) | I9: =IF( TRIM(tabSuperdettagli[[#This Row],[Raggr. X Struttura]])> "", TRIM(tabSuperdettagli[[#This Row],[Raggr. X Struttura]]), TRIM(tabSuperdettagli[[#This Row],[Resp DT]] ) ) -> Gruppo struttura 1 | J9: =tabSuperdettagli[[#This Row],[Total]] -> 3055 | K9: =tabSuperdettagli[[#This Row],[01.2025]] -> 301 | L9: =tabSuperdettagli[[#This Row],[02.2025]] -> 302 | M9: =tabSuperdettagli[[#This Row],[03.2025]] -> 303 | N9: =tabSuperdettagli[[#This Row],[04.2025]] -> 304 | O9: =tabSuperdettagli[[#This Row],[05.2025]] -> 305 | P9: =tabSuperdettagli[[#This Row],[06.2025]] -> 306 | Q9: =tabSuperdettagli[[#This Row],[07.2025]] -> 307 | R9: =tabSuperdettagli[[#This Row],[08.2025]] -> 308 | S9: =tabSuperdettagli[[#This Row],[09.2025]] -> 309 | T9: =tabSuperdettagli[[#This Row],[10.2025]] -> 310 | U9: =tabSuperdettagli[[#This Row],[11.2025]] -> 0 | V9: =tabSuperdettagli[[#This Row],[12.2025]] -> 0 | W9: =tabSuperdettagli[[#This Row],[INT/EST]] -> Int. | X9: =tabSuperdettagli[[#This Row],[Resp 2°liv]]&"" | Y9: =INDEX( tab_resp1liv[EngUnit area cluster 1_], MATCH( SUBSTITUTE(tabSuperdettagli[[#This Row],[Resp 2°liv]], " ", ""), tab_resp1liv[SearchKey],0)) -> #N/A | Z9: =tabSuperdettagli[[#This Row],[WBS Element]]&"" | AA9: =tabSuperdettagli[[#This Row],[09.2025]] -> 309 | AC9: =IF( tabSuperdettagli[[#This Row],[ProjType_]]="M", IF( AND(tabSuperdettagli[[#This Row],[Resp 1°liv_]]="Guidotti C.", tabSuperdettagli[[#This Row],[WBE description_]]="Machine Mgmt"), "Documentation", tabSuperdettagli[[#This Row],[WBE description_]]), "" ) | AD9: =LEFT(tabSuperdettagli[[#This Row],[Network]], 18 ) | AE9: Send cost A | AP9: Int. | AQ9: Gruppo struttura 1 | AV9: Responsabile A | BJ9: 301 | BK9: 302 | BL9: 303 | BM9: 304 | BN9: 305 | BO9: 306 | BP9: 307 | BQ9: 308 | BR9: 309 | BS9: 310 | BV9: 3055 | BX9: 42024 | CB9: 42023 | CC9: 42063
A10: =IF(UPPER(LEFT(tabSuperdettagli[[#This Row],[WBE Status]],1))="S","sì","no") -> no | B10: 2015 | C10: =VLOOKUP(tabSuperdettagli[[#This Row],[WBS_]],Pivot_AnnoPrimaMarcatura!A:B,2,FALSE) -> #N/A | D10: =LEFT(tabSuperdettagli[[#This Row],[Network]], 10) | E10: =LEFT(tabSuperdettagli[[#This Row],[Network]], 1) | F10: =LOWER(TRIM( tabSuperdettagli[[#This Row],[Proj. Type ]] )) | G10: =IF( OR( tabSuperdettagli[[#This Row],[ProjType_]]="C", tabSuperdettagli[[#This Row],[ProjType_]]="A", tabSuperdettagli[[#This Row],[ProjType_]]="R", tabSuperdettagli[[#This Row],[ProjType_]]="E"), "C A R E", IF( tabSuperdettagli[[#This Row],[ProjType_]]="U", "U (" & tabSuperdettagli[[#This Row],[U ProjType_]] & ")", tabSuperdettagli[[#This Row],[ProjType_]]) ) | I10: =IF( TRIM(tabSuperdettagli[[#This Row],[Raggr. X Struttura]])> "", TRIM(tabSuperdettagli[[#This Row],[Raggr. X Struttura]]), TRIM(tabSuperdettagli[[#This Row],[Resp DT]] ) ) -> Gruppo struttura 6 | J10: =tabSuperdettagli[[#This Row],[Total]] -> 4055 | K10: =tabSuperdettagli[[#This Row],[01.2025]] -> 401 | L10: =tabSuperdettagli[[#This Row],[02.2025]] -> 402 | M10: =tabSuperdettagli[[#This Row],[03.2025]] -> 403 | N10: =tabSuperdettagli[[#This Row],[04.2025]] -> 404 | O10: =tabSuperdettagli[[#This Row],[05.2025]] -> 405 | P10: =tabSuperdettagli[[#This Row],[06.2025]] -> 406 | Q10: =tabSuperdettagli[[#This Row],[07.2025]] -> 407 | R10: =tabSuperdettagli[[#This Row],[08.2025]] -> 408 | S10: =tabSuperdettagli[[#This Row],[09.2025]] -> 409 | T10: =tabSuperdettagli[[#This Row],[10.2025]] -> 410 | U10: =tabSuperdettagli[[#This Row],[11.2025]] -> 0 | V10: =tabSuperdettagli[[#This Row],[12.2025]] -> 0 | W10: =tabSuperdettagli[[#This Row],[INT/EST]] -> Int. | X10: =tabSuperdettagli[[#This Row],[Resp 2°liv]]&"" | Y10: =INDEX( tab_resp1liv[EngUnit area cluster 1_], MATCH( SUBSTITUTE(tabSuperdettagli[[#This Row],[Resp 2°liv]], " ", ""), tab_resp1liv[SearchKey],0)) -> #N/A | Z10: =tabSuperdettagli[[#This Row],[WBS Element]]&"" | AA10: =tabSuperdettagli[[#This Row],[09.2025]] -> 409 | AC10: =IF( tabSuperdettagli[[#This Row],[ProjType_]]="M", IF( AND(tabSuperdettagli[[#This Row],[Resp 1°liv_]]="Guidotti C.", tabSuperdettagli[[#This Row],[WBE description_]]="Machine Mgmt"), "Documentation", tabSuperdettagli[[#This Row],[WBE description_]]), "" ) | AD10: =LEFT(tabSuperdettagli[[#This Row],[Network]], 18 ) | AE10: Send cost A | AP10: Int. | AQ10: Gruppo struttura 6 | AV10: Responsabile A | BJ10: 401 | BK10: 402 | BL10: 403 | BM10: 404 | BN10: 405 | BO10: 406 | BP10: 407 | BQ10: 408 | BR10: 409 | BS10: 410 | BV10: 4055 | BX10: 42027 | CB10: 42026 | CC10: 42066
A11: =IF(UPPER(LEFT(tabSuperdettagli[[#This Row],[WBE Status]],1))="S","sì","no") -> no | B11: 2015 | C11: =VLOOKUP(tabSuperdettagli[[#This Row],[WBS_]],Pivot_AnnoPrimaMarcatura!A:B,2,FALSE) -> #N/A | D11: =LEFT(tabSuperdettagli[[#This Row],[Network]], 10) | E11: =LEFT(tabSuperdettagli[[#This Row],[Network]], 1) | F11: =LOWER(TRIM( tabSuperdettagli[[#This Row],[Proj. Type ]] )) | G11: =IF( OR( tabSuperdettagli[[#This Row],[ProjType_]]="C", tabSuperdettagli[[#This Row],[ProjType_]]="A", tabSuperdettagli[[#This Row],[ProjType_]]="R", tabSuperdettagli[[#This Row],[ProjType_]]="E"), "C A R E", IF( tabSuperdettagli[[#This Row],[ProjType_]]="U", "U (" & tabSuperdettagli[[#This Row],[U ProjType_]] & ")", tabSuperdettagli[[#This Row],[ProjType_]]) ) | I11: =IF( TRIM(tabSuperdettagli[[#This Row],[Raggr. X Struttura]])> "", TRIM(tabSuperdettagli[[#This Row],[Raggr. X Struttura]]), TRIM(tabSuperdettagli[[#This Row],[Resp DT]] ) ) -> Gruppo struttura 1 | J11: =tabSuperdettagli[[#This Row],[Total]] -> 55 | K11: =tabSuperdettagli[[#This Row],[01.2025]] -> 1 | L11: =tabSuperdettagli[[#This Row],[02.2025]] -> 2 | M11: =tabSuperdettagli[[#This Row],[03.2025]] -> 3 | N11: =tabSuperdettagli[[#This Row],[04.2025]] -> 4 | O11: =tabSuperdettagli[[#This Row],[05.2025]] -> 5 | P11: =tabSuperdettagli[[#This Row],[06.2025]] -> 6 | Q11: =tabSuperdettagli[[#This Row],[07.2025]] -> 7 | R11: =tabSuperdettagli[[#This Row],[08.2025]] -> 8 | S11: =tabSuperdettagli[[#This Row],[09.2025]] -> 9 | T11: =tabSuperdettagli[[#This Row],[10.2025]] -> 10 | U11: =tabSuperdettagli[[#This Row],[11.2025]] -> 0 | V11: =tabSuperdettagli[[#This Row],[12.2025]] -> 0 | W11: =tabSuperdettagli[[#This Row],[INT/EST]] -> Int. | X11: =tabSuperdettagli[[#This Row],[Resp 2°liv]]&"" | Y11: =INDEX( tab_resp1liv[EngUnit area cluster 1_], MATCH( SUBSTITUTE(tabSuperdettagli[[#This Row],[Resp 2°liv]], " ", ""), tab_resp1liv[SearchKey],0)) -> #N/A | Z11: =tabSuperdettagli[[#This Row],[WBS Element]]&"" | AA11: =tabSuperdettagli[[#This Row],[09.2025]] -> 9 | AC11: =IF( tabSuperdettagli[[#This Row],[ProjType_]]="M", IF( AND(tabSuperdettagli[[#This Row],[Resp 1°liv_]]="Guidotti C.", tabSuperdettagli[[#This Row],[WBE description_]]="Machine Mgmt"), "Documentation", tabSuperdettagli[[#This Row],[WBE description_]]), "" ) | AD11: =LEFT(tabSuperdettagli[[#This Row],[Network]], 18 ) | AE11: Send cost A | AP11: Int. | AQ11: Gruppo struttura 1 | AV11: Responsabile A | BJ11: 1 | BK11: 2 | BL11: 3 | BM11: 4 | BN11: 5 | BO11: 6 | BP11: 7 | BQ11: 8 | BR11: 9 | BS11: 10 | BV11: 55 | BX11: 42030 | CB11: 42029 | CC11: 42069
A12: =IF(UPPER(LEFT(tabSuperdettagli[[#This Row],[WBE Status]],1))="S","sì","no") -> no | B12: 2015 | C12: =VLOOKUP(tabSuperdettagli[[#This Row],[WBS_]],Pivot_AnnoPrimaMarcatura!A:B,2,FALSE) -> #N/A | D12: =LEFT(tabSuperdettagli[[#This Row],[Network]], 10) | E12: =LEFT(tabSuperdettagli[[#This Row],[Network]], 1) | F12: =LOWER(TRIM( tabSuperdettagli[[#This Row],[Proj. Type ]] )) | G12: =IF( OR( tabSuperdettagli[[#This Row],[ProjType_]]="C", tabSuperdettagli[[#This Row],[ProjType_]]="A", tabSuperdettagli[[#This Row],[ProjType_]]="R", tabSuperdettagli[[#This Row],[ProjType_]]="E"), "C A R E", IF( tabSuperdettagli[[#This Row],[ProjType_]]="U", "U (" & tabSuperdettagli[[#This Row],[U ProjType_]] & ")", tabSuperdettagli[[#This Row],[ProjType_]]) ) | I12: =IF( TRIM(tabSuperdettagli[[#This Row],[Raggr. X Struttura]])> "", TRIM(tabSuperdettagli[[#This Row],[Raggr. X Struttura]]), TRIM(tabSuperdettagli[[#This Row],[Resp DT]] ) ) -> Gruppo struttura 1 | J12: =tabSuperdettagli[[#This Row],[Total]] -> 1055 | K12: =tabSuperdettagli[[#This Row],[01.2025]] -> 101 | L12: =tabSuperdettagli[[#This Row],[02.2025]] -> 102 | M12: =tabSuperdettagli[[#This Row],[03.2025]] -> 103 | N12: =tabSuperdettagli[[#This Row],[04.2025]] -> 104 | O12: =tabSuperdettagli[[#This Row],[05.2025]] -> 105 | P12: =tabSuperdettagli[[#This Row],[06.2025]] -> 106 | Q12: =tabSuperdettagli[[#This Row],[07.2025]] -> 107 | R12: =tabSuperdettagli[[#This Row],[08.2025]] -> 108 | S12: =tabSuperdettagli[[#This Row],[09.2025]] -> 109 | T12: =tabSuperdettagli[[#This Row],[10.2025]] -> 110 | U12: =tabSuperdettagli[[#This Row],[11.2025]] -> 0 | V12: =tabSuperdettagli[[#This Row],[12.2025]] -> 0 | W12: =tabSuperdettagli[[#This Row],[INT/EST]] -> Int. | X12: =tabSuperdettagli[[#This Row],[Resp 2°liv]]&"" | Y12: =INDEX( tab_resp1liv[EngUnit area cluster 1_], MATCH( SUBSTITUTE(tabSuperdettagli[[#This Row],[Resp 2°liv]], " ", ""), tab_resp1liv[SearchKey],0)) -> #N/A | Z12: =tabSuperdettagli[[#This Row],[WBS Element]]&"" | AA12: =tabSuperdettagli[[#This Row],[09.2025]] -> 109 | AC12: =IF( tabSuperdettagli[[#This Row],[ProjType_]]="M", IF( AND(tabSuperdettagli[[#This Row],[Resp 1°liv_]]="Guidotti C.", tabSuperdettagli[[#This Row],[WBE description_]]="Machine Mgmt"), "Documentation", tabSuperdettagli[[#This Row],[WBE description_]]), "" ) | AD12: =LEFT(tabSuperdettagli[[#This Row],[Network]], 18 ) | AE12: Send cost A | AP12: Int. | AQ12: Gruppo struttura 1 | AV12: Responsabile B | BJ12: 101 | BK12: 102 | BL12: 103 | BM12: 104 | BN12: 105 | BO12: 106 | BP12: 107 | BQ12: 108 | BR12: 109 | BS12: 110 | BV12: 1055 | BX12: 42033 | CB12: 42032 | CC12: 42072
A13: =IF(UPPER(LEFT(tabSuperdettagli[[#This Row],[WBE Status]],1))="S","sì","no") -> no | B13: 2016 | C13: =VLOOKUP(tabSuperdettagli[[#This Row],[WBS_]],Pivot_AnnoPrimaMarcatura!A:B,2,FALSE) -> #N/A | D13: =LEFT(tabSuperdettagli[[#This Row],[Network]], 10) | E13: =LEFT(tabSuperdettagli[[#This Row],[Network]], 1) | F13: =LOWER(TRIM( tabSuperdettagli[[#This Row],[Proj. Type ]] )) | G13: =IF( OR( tabSuperdettagli[[#This Row],[ProjType_]]="C", tabSuperdettagli[[#This Row],[ProjType_]]="A", tabSuperdettagli[[#This Row],[ProjType_]]="R", tabSuperdettagli[[#This Row],[ProjType_]]="E"), "C A R E", IF( tabSuperdettagli[[#This Row],[ProjType_]]="U", "U (" & tabSuperdettagli[[#This Row],[U ProjType_]] & ")", tabSuperdettagli[[#This Row],[ProjType_]]) ) | I13: =IF( TRIM(tabSuperdettagli[[#This Row],[Raggr. X Struttura]])> "", TRIM(tabSuperdettagli[[#This Row],[Raggr. X Struttura]]), TRIM(tabSuperdettagli[[#This Row],[Resp DT]] ) ) -> Gruppo struttura 1 | J13: =tabSuperdettagli[[#This Row],[Total]] -> 2055 | K13: =tabSuperdettagli[[#This Row],[01.2025]] -> 201 | L13: =tabSuperdettagli[[#This Row],[02.2025]] -> 202 | M13: =tabSuperdettagli[[#This Row],[03.2025]] -> 203 | N13: =tabSuperdettagli[[#This Row],[04.2025]] -> 204 | O13: =tabSuperdettagli[[#This Row],[05.2025]] -> 205 | P13: =tabSuperdettagli[[#This Row],[06.2025]] -> 206 | Q13: =tabSuperdettagli[[#This Row],[07.2025]] -> 207 | R13: =tabSuperdettagli[[#This Row],[08.2025]] -> 208 | S13: =tabSuperdettagli[[#This Row],[09.2025]] -> 209 | T13: =tabSuperdettagli[[#This Row],[10.2025]] -> 210 | U13: =tabSuperdettagli[[#This Row],[11.2025]] -> 0 | V13: =tabSuperdettagli[[#This Row],[12.2025]] -> 0 | W13: =tabSuperdettagli[[#This Row],[INT/EST]] -> Int. | X13: =tabSuperdettagli[[#This Row],[Resp 2°liv]]&"" | Y13: =INDEX( tab_resp1liv[EngUnit area cluster 1_], MATCH( SUBSTITUTE(tabSuperdettagli[[#This Row],[Resp 2°liv]], " ", ""), tab_resp1liv[SearchKey],0)) -> #N/A | Z13: =tabSuperdettagli[[#This Row],[WBS Element]]&"" | AA13: =tabSuperdettagli[[#This Row],[09.2025]] -> 209 | AC13: =IF( tabSuperdettagli[[#This Row],[ProjType_]]="M", IF( AND(tabSuperdettagli[[#This Row],[Resp 1°liv_]]="Guidotti C.", tabSuperdettagli[[#This Row],[WBE description_]]="Machine Mgmt"), "Documentation", tabSuperdettagli[[#This Row],[WBE description_]]), "" ) | AD13: =LEFT(tabSuperdettagli[[#This Row],[Network]], 18 ) | AE13: Send cost B | AP13: Int. | AQ13: Gruppo struttura 1 | AV13: Responsabile A | BJ13: 201 | BK13: 202 | BL13: 203 | BM13: 204 | BN13: 205 | BO13: 206 | BP13: 207 | BQ13: 208 | BR13: 209 | BS13: 210 | BV13: 2055 | BX13: 42036 | CB13: 42035 | CC13: 42075
A14: =IF(UPPER(LEFT(tabSuperdettagli[[#This Row],[WBE Status]],1))="S","sì","no") -> no | B14: 2016 | C14: =VLOOKUP(tabSuperdettagli[[#This Row],[WBS_]],Pivot_AnnoPrimaMarcatura!A:B,2,FALSE) -> #N/A | D14: =LEFT(tabSuperdettagli[[#This Row],[Network]], 10) | E14: =LEFT(tabSuperdettagli[[#This Row],[Network]], 1) | F14: =LOWER(TRIM( tabSuperdettagli[[#This Row],[Proj. Type ]] )) | G14: =IF( OR( tabSuperdettagli[[#This Row],[ProjType_]]="C", tabSuperdettagli[[#This Row],[ProjType_]]="A", tabSuperdettagli[[#This Row],[ProjType_]]="R", tabSuperdettagli[[#This Row],[ProjType_]]="E"), "C A R E", IF( tabSuperdettagli[[#This Row],[ProjType_]]="U", "U (" & tabSuperdettagli[[#This Row],[U ProjType_]] & ")", tabSuperdettagli[[#This Row],[ProjType_]]) ) | I14: =IF( TRIM(tabSuperdettagli[[#This Row],[Raggr. X Struttura]])> "", TRIM(tabSuperdettagli[[#This Row],[Raggr. X Struttura]]), TRIM(tabSuperdettagli[[#This Row],[Resp DT]] ) ) -> Gruppo struttura 1 | J14: =tabSuperdettagli[[#This Row],[Total]] -> 3055 | K14: =tabSuperdettagli[[#This Row],[01.2025]] -> 301 | L14: =tabSuperdettagli[[#This Row],[02.2025]] -> 302 | M14: =tabSuperdettagli[[#This Row],[03.2025]] -> 303 | N14: =tabSuperdettagli[[#This Row],[04.2025]] -> 304 | O14: =tabSuperdettagli[[#This Row],[05.2025]] -> 305 | P14: =tabSuperdettagli[[#This Row],[06.2025]] -> 306 | Q14: =tabSuperdettagli[[#This Row],[07.2025]] -> 307 | R14: =tabSuperdettagli[[#This Row],[08.2025]] -> 308 | S14: =tabSuperdettagli[[#This Row],[09.2025]] -> 309 | T14: =tabSuperdettagli[[#This Row],[10.2025]] -> 310 | U14: =tabSuperdettagli[[#This Row],[11.2025]] -> 0 | V14: =tabSuperdettagli[[#This Row],[12.2025]] -> 0 | W14: =tabSuperdettagli[[#This Row],[INT/EST]] -> Int. | X14: =tabSuperdettagli[[#This Row],[Resp 2°liv]]&"" | Y14: =INDEX( tab_resp1liv[EngUnit area cluster 1_], MATCH( SUBSTITUTE(tabSuperdettagli[[#This Row],[Resp 2°liv]], " ", ""), tab_resp1liv[SearchKey],0)) -> #N/A | Z14: =tabSuperdettagli[[#This Row],[WBS Element]]&"" | AA14: =tabSuperdettagli[[#This Row],[09.2025]] -> 309 | AC14: =IF( tabSuperdettagli[[#This Row],[ProjType_]]="M", IF( AND(tabSuperdettagli[[#This Row],[Resp 1°liv_]]="Guidotti C.", tabSuperdettagli[[#This Row],[WBE description_]]="Machine Mgmt"), "Documentation", tabSuperdettagli[[#This Row],[WBE description_]]), "" ) | AD14: =LEFT(tabSuperdettagli[[#This Row],[Network]], 18 ) | AE14: Send cost B | AP14: Int. | AQ14: Gruppo struttura 1 | AV14: Responsabile C | BJ14: 301 | BK14: 302 | BL14: 303 | BM14: 304 | BN14: 305 | BO14: 306 | BP14: 307 | BQ14: 308 | BR14: 309 | BS14: 310 | BV14: 3055 | BX14: 42039 | CB14: 42038 | CC14: 42078
A15: =IF(UPPER(LEFT(tabSuperdettagli[[#This Row],[WBE Status]],1))="S","sì","no") -> no | B15: 2016 | C15: =VLOOKUP(tabSuperdettagli[[#This Row],[WBS_]],Pivot_AnnoPrimaMarcatura!A:B,2,FALSE) -> #N/A | D15: =LEFT(tabSuperdettagli[[#This Row],[Network]], 10) | E15: =LEFT(tabSuperdettagli[[#This Row],[Network]], 1) | F15: =LOWER(TRIM( tabSuperdettagli[[#This Row],[Proj. Type ]] )) | G15: =IF( OR( tabSuperdettagli[[#This Row],[ProjType_]]="C", tabSuperdettagli[[#This Row],[ProjType_]]="A", tabSuperdettagli[[#This Row],[ProjType_]]="R", tabSuperdettagli[[#This Row],[ProjType_]]="E"), "C A R E", IF( tabSuperdettagli[[#This Row],[ProjType_]]="U", "U (" & tabSuperdettagli[[#This Row],[U ProjType_]] & ")", tabSuperdettagli[[#This Row],[ProjType_]]) ) | I15: =IF( TRIM(tabSuperdettagli[[#This Row],[Raggr. X Struttura]])> "", TRIM(tabSuperdettagli[[#This Row],[Raggr. X Struttura]]), TRIM(tabSuperdettagli[[#This Row],[Resp DT]] ) ) -> Gruppo struttura 1 | J15: =tabSuperdettagli[[#This Row],[Total]] -> 4055 | K15: =tabSuperdettagli[[#This Row],[01.2025]] -> 401 | L15: =tabSuperdettagli[[#This Row],[02.2025]] -> 402 | M15: =tabSuperdettagli[[#This Row],[03.2025]] -> 403 | N15: =tabSuperdettagli[[#This Row],[04.2025]] -> 404 | O15: =tabSuperdettagli[[#This Row],[05.2025]] -> 405 | P15: =tabSuperdettagli[[#This Row],[06.2025]] -> 406 | Q15: =tabSuperdettagli[[#This Row],[07.2025]] -> 407 | R15: =tabSuperdettagli[[#This Row],[08.2025]] -> 408 | S15: =tabSuperdettagli[[#This Row],[09.2025]] -> 409 | T15: =tabSuperdettagli[[#This Row],[10.2025]] -> 410 | U15: =tabSuperdettagli[[#This Row],[11.2025]] -> 0 | V15: =tabSuperdettagli[[#This Row],[12.2025]] -> 0 | W15: =tabSuperdettagli[[#This Row],[INT/EST]] -> Est. | X15: =tabSuperdettagli[[#This Row],[Resp 2°liv]]&"" | Y15: =INDEX( tab_resp1liv[EngUnit area cluster 1_], MATCH( SUBSTITUTE(tabSuperdettagli[[#This Row],[Resp 2°liv]], " ", ""), tab_resp1liv[SearchKey],0)) -> #N/A | Z15: =tabSuperdettagli[[#This Row],[WBS Element]]&"" | AA15: =tabSuperdettagli[[#This Row],[09.2025]] -> 409 | AC15: =IF( tabSuperdettagli[[#This Row],[ProjType_]]="M", IF( AND(tabSuperdettagli[[#This Row],[Resp 1°liv_]]="Guidotti C.", tabSuperdettagli[[#This Row],[WBE description_]]="Machine Mgmt"), "Documentation", tabSuperdettagli[[#This Row],[WBE description_]]), "" ) | AD15: =LEFT(tabSuperdettagli[[#This Row],[Network]], 18 ) | AE15: Send cost B | AP15: Est. | AQ15: Gruppo struttura 1 | AV15: Responsabile A | BJ15: 401 | BK15: 402 | BL15: 403 | BM15: 404 | BN15: 405 | BO15: 406 | BP15: 407 | BQ15: 408 | BR15: 409 | BS15: 410 | BV15: 4055 | BX15: 42042 | CB15: 42041 | CC15: 42081
... A21: =IF(UPPER(LEFT(tabSuperdettagli[[#This Row],[WBE Status]],1))="S","sì","no") -> no | B21: 2016 | C21: =VLOOKUP(tabSuperdettagli[[#This Row],[WBS_]],Pivot_AnnoPrimaMarcatura!A:B,2,FALSE) -> #N/A | D21: =LEFT(tabSuperdettagli[[#This Row],[Network]], 10) | E21: =LEFT(tabSuperdettagli[[#This Row],[Network]], 1) | F21: =LOWER(TRIM( tabSuperdettagli[[#This Row],[Proj. Type ]] )) | G21: =IF( OR( tabSuperdettagli[[#This Row],[ProjType_]]="C", tabSuperdettagli[[#This Row],[ProjType_]]="A", tabSuperdettagli[[#This Row],[ProjType_]]="R", tabSuperdettagli[[#This Row],[ProjType_]]="E"), "C A R E", IF( tabSuperdettagli[[#This Row],[ProjType_]]="U", "U (" & tabSuperdettagli[[#This Row],[U ProjType_]] & ")", tabSuperdettagli[[#This Row],[ProjType_]]) ) | I21: =IF( TRIM(tabSuperdettagli[[#This Row],[Raggr. X Struttura]])> "", TRIM(tabSuperdettagli[[#This Row],[Raggr. X Struttura]]), TRIM(tabSuperdettagli[[#This Row],[Resp DT]] ) ) -> Gruppo struttura 5 | J21: =tabSuperdettagli[[#This Row],[Total]] -> 55 | K21: =tabSuperdettagli[[#This Row],[01.2025]] -> 1 | L21: =tabSuperdettagli[[#This Row],[02.2025]] -> 2 | M21: =tabSuperdettagli[[#This Row],[03.2025]] -> 3 | N21: =tabSuperdettagli[[#This Row],[04.2025]] -> 4 | O21: =tabSuperdettagli[[#This Row],[05.2025]] -> 5 | P21: =tabSuperdettagli[[#This Row],[06.2025]] -> 6 | Q21: =tabSuperdettagli[[#This Row],[07.2025]] -> 7 | R21: =tabSuperdettagli[[#This Row],[08.2025]] -> 8 | S21: =tabSuperdettagli[[#This Row],[09.2025]] -> 9 | T21: =tabSuperdettagli[[#This Row],[10.2025]] -> 10 | U21: =tabSuperdettagli[[#This Row],[11.2025]] -> 0 | V21: =tabSuperdettagli[[#This Row],[12.2025]] -> 0 | W21: =tabSuperdettagli[[#This Row],[INT/EST]] -> Int. | X21: =tabSuperdettagli[[#This Row],[Resp 2°liv]]&"" | Y21: =INDEX( tab_resp1liv[EngUnit area cluster 1_], MATCH( SUBSTITUTE(tabSuperdettagli[[#This Row],[Resp 2°liv]], " ", ""), tab_resp1liv[SearchKey],0)) -> #N/A | Z21: =tabSuperdettagli[[#This Row],[WBS Element]]&"" | AA21: =tabSuperdettagli[[#This Row],[09.2025]] -> 9 | AC21: =IF( tabSuperdettagli[[#This Row],[ProjType_]]="M", IF( AND(tabSuperdettagli[[#This Row],[Resp 1°liv_]]="Guidotti C.", tabSuperdettagli[[#This Row],[WBE description_]]="Machine Mgmt"), "Documentation", tabSuperdettagli[[#This Row],[WBE description_]]), "" ) | AD21: =LEFT(tabSuperdettagli[[#This Row],[Network]], 18 ) | AE21: Send cost B | AP21: Int. | AQ21: Gruppo struttura 5 | AV21: Responsabile C | BJ21: 1 | BK21: 2 | BL21: 3 | BM21: 4 | BN21: 5 | BO21: 6 | BP21: 7 | BQ21: 8 | BR21: 9 | BS21: 10 | BV21: 55 | BX21: 42060 | CB21: 42059 | CC21: 42099
A22: =IF(UPPER(LEFT(tabSuperdettagli[[#This Row],[WBE Status]],1))="S","sì","no") -> no | B22: 2016 | C22: =VLOOKUP(tabSuperdettagli[[#This Row],[WBS_]],Pivot_AnnoPrimaMarcatura!A:B,2,FALSE) -> #N/A | D22: =LEFT(tabSuperdettagli[[#This Row],[Network]], 10) | E22: =LEFT(tabSuperdettagli[[#This Row],[Network]], 1) | F22: =LOWER(TRIM( tabSuperdettagli[[#This Row],[Proj. Type ]] )) | G22: =IF( OR( tabSuperdettagli[[#This Row],[ProjType_]]="C", tabSuperdettagli[[#This Row],[ProjType_]]="A", tabSuperdettagli[[#This Row],[ProjType_]]="R", tabSuperdettagli[[#This Row],[ProjType_]]="E"), "C A R E", IF( tabSuperdettagli[[#This Row],[ProjType_]]="U", "U (" & tabSuperdettagli[[#This Row],[U ProjType_]] & ")", tabSuperdettagli[[#This Row],[ProjType_]]) ) | I22: =IF( TRIM(tabSuperdettagli[[#This Row],[Raggr. X Struttura]])> "", TRIM(tabSuperdettagli[[#This Row],[Raggr. X Struttura]]), TRIM(tabSuperdettagli[[#This Row],[Resp DT]] ) ) -> Responsabile B | J22: =tabSuperdettagli[[#This Row],[Total]] -> 1055 | K22: =tabSuperdettagli[[#This Row],[01.2025]] -> 101 | L22: =tabSuperdettagli[[#This Row],[02.2025]] -> 102 | M22: =tabSuperdettagli[[#This Row],[03.2025]] -> 103 | N22: =tabSuperdettagli[[#This Row],[04.2025]] -> 104 | O22: =tabSuperdettagli[[#This Row],[05.2025]] -> 105 | P22: =tabSuperdettagli[[#This Row],[06.2025]] -> 106 | Q22: =tabSuperdettagli[[#This Row],[07.2025]] -> 107 | R22: =tabSuperdettagli[[#This Row],[08.2025]] -> 108 | S22: =tabSuperdettagli[[#This Row],[09.2025]] -> 109 | T22: =tabSuperdettagli[[#This Row],[10.2025]] -> 110 | U22: =tabSuperdettagli[[#This Row],[11.2025]] -> 0 | V22: =tabSuperdettagli[[#This Row],[12.2025]] -> 0 | W22: =tabSuperdettagli[[#This Row],[INT/EST]] -> Int. | X22: =tabSuperdettagli[[#This Row],[Resp 2°liv]]&"" | Y22: =INDEX( tab_resp1liv[EngUnit area cluster 1_], MATCH( SUBSTITUTE(tabSuperdettagli[[#This Row],[Resp 2°liv]], " ", ""), tab_resp1liv[SearchKey],0)) -> #N/A | Z22: =tabSuperdettagli[[#This Row],[WBS Element]]&"" | AA22: =tabSuperdettagli[[#This Row],[09.2025]] -> 109 | AC22: =IF( tabSuperdettagli[[#This Row],[ProjType_]]="M", IF( AND(tabSuperdettagli[[#This Row],[Resp 1°liv_]]="Guidotti C.", tabSuperdettagli[[#This Row],[WBE description_]]="Machine Mgmt"), "Documentation", tabSuperdettagli[[#This Row],[WBE description_]]), "" ) | AD22: =LEFT(tabSuperdettagli[[#This Row],[Network]], 18 ) | AE22: Send cost B | AP22: Int. | AV22: Responsabile B | BJ22: 101 | BK22: 102 | BL22: 103 | BM22: 104 | BN22: 105 | BO22: 106 | BP22: 107 | BQ22: 108 | BR22: 109 | BS22: 110 | BV22: 1055 | BX22: 42063 | CB22: 42062 | CC22: 42102
A23: =IF(UPPER(LEFT(tabSuperdettagli[[#This Row],[WBE Status]],1))="S","sì","no") -> no | B23: 2017 | C23: =VLOOKUP(tabSuperdettagli[[#This Row],[WBS_]],Pivot_AnnoPrimaMarcatura!A:B,2,FALSE) -> #N/A | D23: =LEFT(tabSuperdettagli[[#This Row],[Network]], 10) | E23: =LEFT(tabSuperdettagli[[#This Row],[Network]], 1) | F23: =LOWER(TRIM( tabSuperdettagli[[#This Row],[Proj. Type ]] )) | G23: =IF( OR( tabSuperdettagli[[#This Row],[ProjType_]]="C", tabSuperdettagli[[#This Row],[ProjType_]]="A", tabSuperdettagli[[#This Row],[ProjType_]]="R", tabSuperdettagli[[#This Row],[ProjType_]]="E"), "C A R E", IF( tabSuperdettagli[[#This Row],[ProjType_]]="U", "U (" & tabSuperdettagli[[#This Row],[U ProjType_]] & ")", tabSuperdettagli[[#This Row],[ProjType_]]) ) | I23: =IF( TRIM(tabSuperdettagli[[#This Row],[Raggr. X Struttura]])> "", TRIM(tabSuperdettagli[[#This Row],[Raggr. X Struttura]]), TRIM(tabSuperdettagli[[#This Row],[Resp DT]] ) ) -> Gruppo struttura 3 | J23: =tabSuperdettagli[[#This Row],[Total]] -> 2055 | K23: =tabSuperdettagli[[#This Row],[01.2025]] -> 201 | L23: =tabSuperdettagli[[#This Row],[02.2025]] -> 202 | M23: =tabSuperdettagli[[#This Row],[03.2025]] -> 203 | N23: =tabSuperdettagli[[#This Row],[04.2025]] -> 204 | O23: =tabSuperdettagli[[#This Row],[05.2025]] -> 205 | P23: =tabSuperdettagli[[#This Row],[06.2025]] -> 206 | Q23: =tabSuperdettagli[[#This Row],[07.2025]] -> 207 | R23: =tabSuperdettagli[[#This Row],[08.2025]] -> 208 | S23: =tabSuperdettagli[[#This Row],[09.2025]] -> 209 | T23: =tabSuperdettagli[[#This Row],[10.2025]] -> 210 | U23: =tabSuperdettagli[[#This Row],[11.2025]] -> 0 | V23: =tabSuperdettagli[[#This Row],[12.2025]] -> 0 | W23: =tabSuperdettagli[[#This Row],[INT/EST]] -> Est. | X23: =tabSuperdettagli[[#This Row],[Resp 2°liv]]&"" | Y23: =INDEX( tab_resp1liv[EngUnit area cluster 1_], MATCH( SUBSTITUTE(tabSuperdettagli[[#This Row],[Resp 2°liv]], " ", ""), tab_resp1liv[SearchKey],0)) -> #N/A | Z23: =tabSuperdettagli[[#This Row],[WBS Element]]&"" | AA23: =tabSuperdettagli[[#This Row],[09.2025]] -> 209 | AC23: =IF( tabSuperdettagli[[#This Row],[ProjType_]]="M", IF( AND(tabSuperdettagli[[#This Row],[Resp 1°liv_]]="Guidotti C.", tabSuperdettagli[[#This Row],[WBE description_]]="Machine Mgmt"), "Documentation", tabSuperdettagli[[#This Row],[WBE description_]]), "" ) | AD23: =LEFT(tabSuperdettagli[[#This Row],[Network]], 18 ) | AE23: Send cost C | AP23: Est. | AQ23: Gruppo struttura 3 | AV23: Responsabile A | BJ23: 201 | BK23: 202 | BL23: 203 | BM23: 204 | BN23: 205 | BO23: 206 | BP23: 207 | BQ23: 208 | BR23: 209 | BS23: 210 | BV23: 2055 | BX23: 42066 | CB23: 42065 | CC23: 42105
A24: =IF(UPPER(LEFT(tabSuperdettagli[[#This Row],[WBE Status]],1))="S","sì","no") -> no | B24: 2017 | C24: =VLOOKUP(tabSuperdettagli[[#This Row],[WBS_]],Pivot_AnnoPrimaMarcatura!A:B,2,FALSE) -> #N/A | D24: =LEFT(tabSuperdettagli[[#This Row],[Network]], 10) | E24: =LEFT(tabSuperdettagli[[#This Row],[Network]], 1) | F24: =LOWER(TRIM( tabSuperdettagli[[#This Row],[Proj. Type ]] )) | G24: =IF( OR( tabSuperdettagli[[#This Row],[ProjType_]]="C", tabSuperdettagli[[#This Row],[ProjType_]]="A", tabSuperdettagli[[#This Row],[ProjType_]]="R", tabSuperdettagli[[#This Row],[ProjType_]]="E"), "C A R E", IF( tabSuperdettagli[[#This Row],[ProjType_]]="U", "U (" & tabSuperdettagli[[#This Row],[U ProjType_]] & ")", tabSuperdettagli[[#This Row],[ProjType_]]) ) | I24: =IF( TRIM(tabSuperdettagli[[#This Row],[Raggr. X Struttura]])> "", TRIM(tabSuperdettagli[[#This Row],[Raggr. X Struttura]]), TRIM(tabSuperdettagli[[#This Row],[Resp DT]] ) ) -> Gruppo struttura 1 | J24: =tabSuperdettagli[[#This Row],[Total]] -> 3055 | K24: =tabSuperdettagli[[#This Row],[01.2025]] -> 301 | L24: =tabSuperdettagli[[#This Row],[02.2025]] -> 302 | M24: =tabSuperdettagli[[#This Row],[03.2025]] -> 303 | N24: =tabSuperdettagli[[#This Row],[04.2025]] -> 304 | O24: =tabSuperdettagli[[#This Row],[05.2025]] -> 305 | P24: =tabSuperdettagli[[#This Row],[06.2025]] -> 306 | Q24: =tabSuperdettagli[[#This Row],[07.2025]] -> 307 | R24: =tabSuperdettagli[[#This Row],[08.2025]] -> 308 | S24: =tabSuperdettagli[[#This Row],[09.2025]] -> 309 | T24: =tabSuperdettagli[[#This Row],[10.2025]] -> 310 | U24: =tabSuperdettagli[[#This Row],[11.2025]] -> 0 | V24: =tabSuperdettagli[[#This Row],[12.2025]] -> 0 | W24: =tabSuperdettagli[[#This Row],[INT/EST]] -> Est. | X24: =tabSuperdettagli[[#This Row],[Resp 2°liv]]&"" | Y24: =INDEX( tab_resp1liv[EngUnit area cluster 1_], MATCH( SUBSTITUTE(tabSuperdettagli[[#This Row],[Resp 2°liv]], " ", ""), tab_resp1liv[SearchKey],0)) -> #N/A | Z24: =tabSuperdettagli[[#This Row],[WBS Element]]&"" | AA24: =tabSuperdettagli[[#This Row],[09.2025]] -> 309 | AC24: =IF( tabSuperdettagli[[#This Row],[ProjType_]]="M", IF( AND(tabSuperdettagli[[#This Row],[Resp 1°liv_]]="Guidotti C.", tabSuperdettagli[[#This Row],[WBE description_]]="Machine Mgmt"), "Documentation", tabSuperdettagli[[#This Row],[WBE description_]]), "" ) | AD24: =LEFT(tabSuperdettagli[[#This Row],[Network]], 18 ) | AE24: Send cost C | AP24: Est. | AQ24: Gruppo struttura 1 | AV24: Responsabile A | BJ24: 301 | BK24: 302 | BL24: 303 | BM24: 304 | BN24: 305 | BO24: 306 | BP24: 307 | BQ24: 308 | BR24: 309 | BS24: 310 | BV24: 3055 | BX24: 42069 | CB24: 42068 | CC24: 42108
A25: =IF(UPPER(LEFT(tabSuperdettagli[[#This Row],[WBE Status]],1))="S","sì","no") -> no | B25: 2017 | C25: =VLOOKUP(tabSuperdettagli[[#This Row],[WBS_]],Pivot_AnnoPrimaMarcatura!A:B,2,FALSE) -> #N/A | D25: =LEFT(tabSuperdettagli[[#This Row],[Network]], 10) | E25: =LEFT(tabSuperdettagli[[#This Row],[Network]], 1) | F25: =LOWER(TRIM( tabSuperdettagli[[#This Row],[Proj. Type ]] )) | G25: =IF( OR( tabSuperdettagli[[#This Row],[ProjType_]]="C", tabSuperdettagli[[#This Row],[ProjType_]]="A", tabSuperdettagli[[#This Row],[ProjType_]]="R", tabSuperdettagli[[#This Row],[ProjType_]]="E"), "C A R E", IF( tabSuperdettagli[[#This Row],[ProjType_]]="U", "U (" & tabSuperdettagli[[#This Row],[U ProjType_]] & ")", tabSuperdettagli[[#This Row],[ProjType_]]) ) | I25: =IF( TRIM(tabSuperdettagli[[#This Row],[Raggr. X Struttura]])> "", TRIM(tabSuperdettagli[[#This Row],[Raggr. X Struttura]]), TRIM(tabSuperdettagli[[#This Row],[Resp DT]] ) ) -> Gruppo struttura 1 | J25: =tabSuperdettagli[[#This Row],[Total]] -> 4055 | K25: =tabSuperdettagli[[#This Row],[01.2025]] -> 401 | L25: =tabSuperdettagli[[#This Row],[02.2025]] -> 402 | M25: =tabSuperdettagli[[#This Row],[03.2025]] -> 403 | N25: =tabSuperdettagli[[#This Row],[04.2025]] -> 404 | O25: =tabSuperdettagli[[#This Row],[05.2025]] -> 405 | P25: =tabSuperdettagli[[#This Row],[06.2025]] -> 406 | Q25: =tabSuperdettagli[[#This Row],[07.2025]] -> 407 | R25: =tabSuperdettagli[[#This Row],[08.2025]] -> 408 | S25: =tabSuperdettagli[[#This Row],[09.2025]] -> 409 | T25: =tabSuperdettagli[[#This Row],[10.2025]] -> 410 | U25: =tabSuperdettagli[[#This Row],[11.2025]] -> 0 | V25: =tabSuperdettagli[[#This Row],[12.2025]] -> 0 | W25: =tabSuperdettagli[[#This Row],[INT/EST]] -> Int. | X25: =tabSuperdettagli[[#This Row],[Resp 2°liv]]&"" | Y25: =INDEX( tab_resp1liv[EngUnit area cluster 1_], MATCH( SUBSTITUTE(tabSuperdettagli[[#This Row],[Resp 2°liv]], " ", ""), tab_resp1liv[SearchKey],0)) -> #N/A | Z25: =tabSuperdettagli[[#This Row],[WBS Element]]&"" | AA25: =tabSuperdettagli[[#This Row],[09.2025]] -> 409 | AC25: =IF( tabSuperdettagli[[#This Row],[ProjType_]]="M", IF( AND(tabSuperdettagli[[#This Row],[Resp 1°liv_]]="Guidotti C.", tabSuperdettagli[[#This Row],[WBE description_]]="Machine Mgmt"), "Documentation", tabSuperdettagli[[#This Row],[WBE description_]]), "" ) | AD25: =LEFT(tabSuperdettagli[[#This Row],[Network]], 18 ) | AE25: Send cost C | AP25: Int. | AQ25: Gruppo struttura 1 | AV25: Responsabile A | BJ25: 401 | BK25: 402 | BL25: 403 | BM25: 404 | BN25: 405 | BO25: 406 | BP25: 407 | BQ25: 408 | BR25: 409 | BS25: 410 | BV25: 4055 | BX25: 42072 | CB25: 42071 | CC25: 42111
A26: =IF(UPPER(LEFT(tabSuperdettagli[[#This Row],[WBE Status]],1))="S","sì","no") -> no | B26: 2017 | C26: =VLOOKUP(tabSuperdettagli[[#This Row],[WBS_]],Pivot_AnnoPrimaMarcatura!A:B,2,FALSE) -> #N/A | D26: =LEFT(tabSuperdettagli[[#This Row],[Network]], 10) | E26: =LEFT(tabSuperdettagli[[#This Row],[Network]], 1) | F26: =LOWER(TRIM( tabSuperdettagli[[#This Row],[Proj. Type ]] )) | G26: =IF( OR( tabSuperdettagli[[#This Row],[ProjType_]]="C", tabSuperdettagli[[#This Row],[ProjType_]]="A", tabSuperdettagli[[#This Row],[ProjType_]]="R", tabSuperdettagli[[#This Row],[ProjType_]]="E"), "C A R E", IF( tabSuperdettagli[[#This Row],[ProjType_]]="U", "U (" & tabSuperdettagli[[#This Row],[U ProjType_]] & ")", tabSuperdettagli[[#This Row],[ProjType_]]) ) | I26: =IF( TRIM(tabSuperdettagli[[#This Row],[Raggr. X Struttura]])> "", TRIM(tabSuperdettagli[[#This Row],[Raggr. X Struttura]]), TRIM(tabSuperdettagli[[#This Row],[Resp DT]] ) ) -> Gruppo struttura 4 | J26: =tabSuperdettagli[[#This Row],[Total]] -> 5055 | K26: =tabSuperdettagli[[#This Row],[01.2025]] -> 501 | L26: =tabSuperdettagli[[#This Row],[02.2025]] -> 502 | M26: =tabSuperdettagli[[#This Row],[03.2025]] -> 503 | N26: =tabSuperdettagli[[#This Row],[04.2025]] -> 504 | O26: =tabSuperdettagli[[#This Row],[05.2025]] -> 505 | P26: =tabSuperdettagli[[#This Row],[06.2025]] -> 506 | Q26: =tabSuperdettagli[[#This Row],[07.2025]] -> 507 | R26: =tabSuperdettagli[[#This Row],[08.2025]] -> 508 | S26: =tabSuperdettagli[[#This Row],[09.2025]] -> 509 | T26: =tabSuperdettagli[[#This Row],[10.2025]] -> 510 | U26: =tabSuperdettagli[[#This Row],[11.2025]] -> 0 | V26: =tabSuperdettagli[[#This Row],[12.2025]] -> 0 | W26: =tabSuperdettagli[[#This Row],[INT/EST]] -> Int. | X26: =tabSuperdettagli[[#This Row],[Resp 2°liv]]&"" | Y26: =INDEX( tab_resp1liv[EngUnit area cluster 1_], MATCH( SUBSTITUTE(tabSuperdettagli[[#This Row],[Resp 2°liv]], " ", ""), tab_resp1liv[SearchKey],0)) -> #N/A | Z26: =tabSuperdettagli[[#This Row],[WBS Element]]&"" | AA26: =tabSuperdettagli[[#This Row],[09.2025]] -> 509 | AC26: =IF( tabSuperdettagli[[#This Row],[ProjType_]]="M", IF( AND(tabSuperdettagli[[#This Row],[Resp 1°liv_]]="Guidotti C.", tabSuperdettagli[[#This Row],[WBE description_]]="Machine Mgmt"), "Documentation", tabSuperdettagli[[#This Row],[WBE description_]]), "" ) | AD26: =LEFT(tabSuperdettagli[[#This Row],[Network]], 18 ) | AE26: Send cost C | AP26: Int. | AQ26: Gruppo struttura 4 | AV26: Responsabile A | BJ26: 501 | BK26: 502 | BL26: 503 | BM26: 504 | BN26: 505 | BO26: 506 | BP26: 507 | BQ26: 508 | BR26: 509 | BS26: 510 | BV26: 5055 | BX26: 42075 | CB26: 42074 | CC26: 42114
A27: =IF(UPPER(LEFT(tabSuperdettagli[[#This Row],[WBE Status]],1))="S","sì","no") -> no | B27: 2017 | C27: =VLOOKUP(tabSuperdettagli[[#This Row],[WBS_]],Pivot_AnnoPrimaMarcatura!A:B,2,FALSE) -> #N/A | D27: =LEFT(tabSuperdettagli[[#This Row],[Network]], 10) | E27: =LEFT(tabSuperdettagli[[#This Row],[Network]], 1) | F27: =LOWER(TRIM( tabSuperdettagli[[#This Row],[Proj. Type ]] )) | G27: =IF( OR( tabSuperdettagli[[#This Row],[ProjType_]]="C", tabSuperdettagli[[#This Row],[ProjType_]]="A", tabSuperdettagli[[#This Row],[ProjType_]]="R", tabSuperdettagli[[#This Row],[ProjType_]]="E"), "C A R E", IF( tabSuperdettagli[[#This Row],[ProjType_]]="U", "U (" & tabSuperdettagli[[#This Row],[U ProjType_]] & ")", tabSuperdettagli[[#This Row],[ProjType_]]) ) | I27: =IF( TRIM(tabSuperdettagli[[#This Row],[Raggr. X Struttura]])> "", TRIM(tabSuperdettagli[[#This Row],[Raggr. X Struttura]]), TRIM(tabSuperdettagli[[#This Row],[Resp DT]] ) ) -> Gruppo struttura 1 | J27: =tabSuperdettagli[[#This Row],[Total]] -> 6055 | K27: =tabSuperdettagli[[#This Row],[01.2025]] -> 601 | L27: =tabSuperdettagli[[#This Row],[02.2025]] -> 602 | M27: =tabSuperdettagli[[#This Row],[03.2025]] -> 603 | N27: =tabSuperdettagli[[#This Row],[04.2025]] -> 604 | O27: =tabSuperdettagli[[#This Row],[05.2025]] -> 605 | P27: =tabSuperdettagli[[#This Row],[06.2025]] -> 606 | Q27: =tabSuperdettagli[[#This Row],[07.2025]] -> 607 | R27: =tabSuperdettagli[[#This Row],[08.2025]] -> 608 | S27: =tabSuperdettagli[[#This Row],[09.2025]] -> 609 | T27: =tabSuperdettagli[[#This Row],[10.2025]] -> 610 | U27: =tabSuperdettagli[[#This Row],[11.2025]] -> 0 | V27: =tabSuperdettagli[[#This Row],[12.2025]] -> 0 | W27: =tabSuperdettagli[[#This Row],[INT/EST]] -> Int. | X27: =tabSuperdettagli[[#This Row],[Resp 2°liv]]&"" | Y27: =INDEX( tab_resp1liv[EngUnit area cluster 1_], MATCH( SUBSTITUTE(tabSuperdettagli[[#This Row],[Resp 2°liv]], " ", ""), tab_resp1liv[SearchKey],0)) -> #N/A | Z27: =tabSuperdettagli[[#This Row],[WBS Element]]&"" | AA27: =tabSuperdettagli[[#This Row],[09.2025]] -> 609 | AC27: =IF( tabSuperdettagli[[#This Row],[ProjType_]]="M", IF( AND(tabSuperdettagli[[#This Row],[Resp 1°liv_]]="Guidotti C.", tabSuperdettagli[[#This Row],[WBE description_]]="Machine Mgmt"), "Documentation", tabSuperdettagli[[#This Row],[WBE description_]]), "" ) | AD27: =LEFT(tabSuperdettagli[[#This Row],[Network]], 18 ) | AE27: Send cost C | AP27: Int. | AQ27: Gruppo struttura 1 | AV27: Responsabile A | BJ27: 601 | BK27: 602 | BL27: 603 | BM27: 604 | BN27: 605 | BO27: 606 | BP27: 607 | BQ27: 608 | BR27: 609 | BS27: 610 | BV27: 6055 | BX27: 42078 | CB27: 42077 | CC27: 42117
A28: =IF(UPPER(LEFT(tabSuperdettagli[[#This Row],[WBE Status]],1))="S","sì","no") -> no | B28: 2017 | C28: =VLOOKUP(tabSuperdettagli[[#This Row],[WBS_]],Pivot_AnnoPrimaMarcatura!A:B,2,FALSE) -> #N/A | D28: =LEFT(tabSuperdettagli[[#This Row],[Network]], 10) | E28: =LEFT(tabSuperdettagli[[#This Row],[Network]], 1) | F28: =LOWER(TRIM( tabSuperdettagli[[#This Row],[Proj. Type ]] )) | G28: =IF( OR( tabSuperdettagli[[#This Row],[ProjType_]]="C", tabSuperdettagli[[#This Row],[ProjType_]]="A", tabSuperdettagli[[#This Row],[ProjType_]]="R", tabSuperdettagli[[#This Row],[ProjType_]]="E"), "C A R E", IF( tabSuperdettagli[[#This Row],[ProjType_]]="U", "U (" & tabSuperdettagli[[#This Row],[U ProjType_]] & ")", tabSuperdettagli[[#This Row],[ProjType_]]) ) | I28: =IF( TRIM(tabSuperdettagli[[#This Row],[Raggr. X Struttura]])> "", TRIM(tabSuperdettagli[[#This Row],[Raggr. X Struttura]]), TRIM(tabSuperdettagli[[#This Row],[Resp DT]] ) ) -> Gruppo struttura 1 | J28: =tabSuperdettagli[[#This Row],[Total]] -> 55 | K28: =tabSuperdettagli[[#This Row],[01.2025]] -> 1 | L28: =tabSuperdettagli[[#This Row],[02.2025]] -> 2 | M28: =tabSuperdettagli[[#This Row],[03.2025]] -> 3 | N28: =tabSuperdettagli[[#This Row],[04.2025]] -> 4 | O28: =tabSuperdettagli[[#This Row],[05.2025]] -> 5 | P28: =tabSuperdettagli[[#This Row],[06.2025]] -> 6 | Q28: =tabSuperdettagli[[#This Row],[07.2025]] -> 7 | R28: =tabSuperdettagli[[#This Row],[08.2025]] -> 8 | S28: =tabSuperdettagli[[#This Row],[09.2025]] -> 9 | T28: =tabSuperdettagli[[#This Row],[10.2025]] -> 10 | U28: =tabSuperdettagli[[#This Row],[11.2025]] -> 0 | V28: =tabSuperdettagli[[#This Row],[12.2025]] -> 0 | W28: =tabSuperdettagli[[#This Row],[INT/EST]] -> Int. | X28: =tabSuperdettagli[[#This Row],[Resp 2°liv]]&"" | Y28: =INDEX( tab_resp1liv[EngUnit area cluster 1_], MATCH( SUBSTITUTE(tabSuperdettagli[[#This Row],[Resp 2°liv]], " ", ""), tab_resp1liv[SearchKey],0)) -> #N/A | Z28: =tabSuperdettagli[[#This Row],[WBS Element]]&"" | AA28: =tabSuperdettagli[[#This Row],[09.2025]] -> 9 | AC28: =IF( tabSuperdettagli[[#This Row],[ProjType_]]="M", IF( AND(tabSuperdettagli[[#This Row],[Resp 1°liv_]]="Guidotti C.", tabSuperdettagli[[#This Row],[WBE description_]]="Machine Mgmt"), "Documentation", tabSuperdettagli[[#This Row],[WBE description_]]), "" ) | AD28: =LEFT(tabSuperdettagli[[#This Row],[Network]], 18 ) | AE28: Send cost C | AP28: Int. | AQ28: Gruppo struttura 1 | AV28: Responsabile A | BJ28: 1 | BK28: 2 | BL28: 3 | BM28: 4 | BN28: 5 | BO28: 6 | BP28: 7 | BQ28: 8 | BR28: 9 | BS28: 10 | BV28: 55 | BX28: 42081 | CB28: 42080 | CC28: 42120
